# 'try..catch'와 에러 핸들링

아무리 프로그래밍에 능한 사람이더라도 에러가 있는 스크립트를 작성할 수 있습니다. 원인은 아마도 실수, 예상치 못한 사용자 입력, 잘못된 서버 응답 등의 수천만 가지 이유 때문일 겁니다.   
   
에러가 발생하면 스크립트는 '죽고'(즉시 중단되고), 콘솔에 에러가 출력됩니다.   
   
그러나 `try..catch`문법을 사용하면 스크립트가 죽는 걸 방지하고, 에러를 '잡아서(catch)' 더 합당한 무언가를 할 수 있게 됩니다.



## 'try...catch' 문법

'try...catch'문법은 'try'와 'catch'라는 두 개의 주요 블록으로 구성됩니다.   
```
try{
  // 코드
} catch (err) {
  // 에러 핸들링
}
```
try...catch 동작 알고리즘은 다음과 같습니다.
   
1. 먼저, `try {...}`안의 코드가 실행됩니다.
2. 에러가 없다면, `try`안의 마지막 줄까지 실행되고, `catch` 블록은 건너뜁니다.
3. 에러가 있다면, `try`안 코드의 실행이 중단되고, `catch(err)`블록으로 제어 흐름이 넘어갑니다. 변수 `err`(아무 이름이나 사용 가능)는 무슨 일이 일어났는지에 대한 설명이 담긴 에러 객체를 포함합니다.   

이렇게 `try {...}` 블록 안에서 에러가 발생해도 `catch`에서 에러를 처리하기 때문에 스크립트는 죽지 않습니다.   

- 에러가 없는 예시 : `(1)`과 `(2)`를 `alert` 창에 보여줌
```
try {
  alert('try 블록 시작');  // (1)  <--
  // ... 에러가 없습니다.
  alert('try 블록 끝');  // (2)  <--
} catch(err) {
  alert('에러가 없으므로, catch는 무시됩니다.');  // (3)
}
```

- 에러가 있는 예시 : `(1)`과 `(3)`을 보여줍니다.
```
try {
  alert('try 블록 시작');  // (1) <--
  lalala;  // 에러, 변수가 정의되지 않음!
  alert('try 블록 끝(절대 도달하지 않음)');  // (2)
} catch(err) {
  alert('에러가 발생했습니다!`);  // (3)  <--
}
```
   
> ❗ `try..catch`는 오직 런타임 에러에만 동작합니다.   
`try..catch`는 실행 가능한 (runnable) 코드에만 동작합니다. 실행 가능한 코드는 유효한 자바스크립트 코드를 의미합니다.   
중괄호 짝이 안 맞는 것처럼 코드가 문법적으로 잘못된 경우엔 `try..catch`가 동작하지 않습니다.
```
try {
  {{{{{{{{{{{{
} catch(e) {
  alert("유효하지 않은 코드이기 때문에, 자바스크립트 엔진은 이 코드를 이해할 수 없습니다.");
}
```
> 자바스크립트 엔진은 코드를 읽고 난 후 코드를 실행합니다. 코드를 읽는 중에 발생하는 에러가 'parse-time 에러'라고 부르는데, 엔진은 이 코드를 이해할 수 없기 때문에 parse-time 에러는 코드 안에서 복구가 불가능합니다.   
`try..catch`는 유효한 코드에서 발생하는 에러만 처리할 수 있습니다. 이런 에러를 '런타임 에러' 혹은 '예외' 라고 부릅니다.   
   
> ❗ `try..catch`는 동기적으로 동작합니다.   
setTimeout처럼 '스케줄 된(scheduled)' 코드에서 발생한 예외는 `try..catch`에서 잡아낼 수 없습니다.   
```
try {
  setTimeout(function() {
    noSuchVariable; // 스크립트는 여기서 죽습니다.
  }, 1000);
} catch (e) {
  alert( "작동 멈춤" );
}
```
> `setTimeout`에 넘겨진 익명 함수는 엔진이 `try..catch`를 떠난 다음에서야 실행되기 때문입니다.   
스케줄 된 함수 내부의 예외를 잡으려면, `try..catch`를 반드시 함수 내부에 구현해야 합니다.
```
setTimeout(function() {
  try {
    noSuchVariable; // 이제 try..catch에서 에러를 핸들링 할 수 있습니다!
  } catch {
    alert( "에러를 잡았습니다!" );
  }
}, 1000);
```
